Workbook

Sheet Cover
A1: CMMC Level 2 Assessment Platform
A3: Assessment readiness, evidence, POA&M, SSP mapping, and weighted scoring workbook
B6: Organization Name
B7: Assessment Name
B8: Assessment Scope
B9: CAGE Code
B10: Assessment Type | C10: Level 2 Self-Assessment
B11: Assessment Start Date
B12: Assessment End Date
B13: Lead Assessor
B14: Workbook Version | C14: 0.2
B15: Assessment Guide | C15: Level 2 Version 2.13
B16: Scoring Source | C16: 32 CFR 170.24
B19: Instructions
B20: Complete the organization metadata above, then evaluate all 110 requirements on the Assessment worksheet. Yellow cells are user-input fields. Gray cells contain formulas or official scoring metadata. Requirements IA.L2-3.5.3 and SC.L2-3.13.11 include limited partial-credit implementation-state options.

Sheet Dashboard
A1: Executive Dashboard
A3: Weighted CMMC Level 2 assessment and readiness summary
B6: Current Score | E6: Requirements Met | H6: Requirements Not Met | K6: Not Assessed
B7: =110-SUM(Assessment!N6:N115) | E7: =COUNTIF(Assessment!I6:I115,"MET") | H7: =COUNTIF(Assessment!I6:I115,"NOT MET") | K7: =COUNTIF(Assessment!I6:I115,"NOT ASSESSED")
B12: Assessment Completion | C12: =IFERROR((COUNTIF(Assessment!I6:I115,"MET")+COUNTIF(Assessment!I6:I115,"NOT MET")+COUNTIF(Assessment!I6:I115,"NOT APPLICABLE"))/110,0) | E12: Evidence Complete | F12: =COUNTIF(Assessment!O6:O115,"Complete") | H12: Partial Credit Applied | I12: =COUNTIF(Assessment!M6:M115,"Yes") | K12: POA&M Items | L12: =COUNTIF(Assessment!S6:S115,"Yes")
B15: Scoring Status | C15: =IF(COUNTIF(Assessment!I6:I115,"NOT ASSESSED")=0,"COMPLETE","PROVISIONAL") | E15: Maximum Deduction | F15: =SUM(Assessment!L6:L115) | H15: Mathematical Minimum | I15: =110-F15

Sheet Assessment
A1: CMMC Level 2 Requirement Assessment
A3: Evaluate implementation, evidence, ownership, SSP mapping, weighted deductions, and POA&M requirements for all 110 controls.
A5: Domain | B5: Requirement ID | C5: Title | D5: Requirement Statement | E5: Source Start | F5: Source End | G5: Applicable | H5: Scoring Category | I5: Status | J5: Implementation State | K5: Partial Credit Allowed | L5: Full Deduction | M5: Partial Credit Applied | N5: Calculated Deduction | O5: Evidence Status | P5: Control Owner | Q5: SSP Reference | R5: Assessor Notes | S5: POA&M Required | T5: Partial Credit Condition | U5: Scoring Source | V5: Score Explanation
A6: AC | B6: AC.L2-3.1.1 | C6: Authorized Access Control [CUI Data] | D6: Limit system access to authorized users, processes acting on behalf of authorized users, and devices (including other systems). | E6: 22 | F6: 24 | G6: Yes | H6: FIVE_POINT | I6: NOT ASSESSED | K6: No | L6: 5 | M6: =IF(AND(K6="Yes",I6="NOT MET",J6="PARTIALLY IMPLEMENTED"),"Yes","No") | N6: =IF(OR(I6="MET",I6="NOT APPLICABLE",I6="NOT ASSESSED"),0,IF(AND(K6="Yes",J6="PARTIALLY IMPLEMENTED"),3,L6)) | O6: Not Started | S6: =IF(I6="NOT MET","Yes","No") | U6: 32 CFR 170.24(c)(2) | Current eCFR | V6: =IF(I6="MET","Requirement assessed MET; no deduction.",IF(I6="NOT APPLICABLE","Requirement assessed NOT APPLICABLE; no deduction.",IF(I6="NOT ASSESSED","Requirement not assessed; score remains provisional.",IF(M6="Yes","Partial-credit condition applied; 3 points deducted.","Requirement assessed NOT MET; "&L6&" points deducted."))))
A7: AC | B7: AC.L2-3.1.2 | C7: Transaction & Function Control | D7: Limit system access to the types of transactions and functions that authorized users are permitted to execute. | E7: 25 | F7: 26 | G7: Yes | H7: FIVE_POINT | I7: NOT ASSESSED | K7: No | L7: 5 | M7: =IF(AND(K7="Yes",I7="NOT MET",J7="PARTIALLY IMPLEMENTED"),"Yes","No") | N7: =IF(OR(I7="MET",I7="NOT APPLICABLE",I7="NOT ASSESSED"),0,IF(AND(K7="Yes",J7="PARTIALLY IMPLEMENTED"),3,L7)) | O7: Not Started | S7: =IF(I7="NOT MET","Yes","No") | U7: 32 CFR 170.24(c)(2) | Current eCFR | V7: =IF(I7="MET","Requirement assessed MET; no deduction.",IF(I7="NOT APPLICABLE","Requirement assessed NOT APPLICABLE; no deduction.",IF(I7="NOT ASSESSED","Requirement not assessed; score remains provisional.",IF(M7="Yes","Partial-credit condition applied; 3 points deducted.","Requirement assessed NOT MET; "&L7&" points deducted."))))
A8: AC | B8: AC.L2-3.1.3 | C8: Control CUI Flow | D8: Control the flow of CUI in accordance with approved authorizations. | E8: 27 | F8: 29 | G8: Yes | H8: ONE_POINT | I8: NOT ASSESSED | K8: No | L8: 1 | M8: =IF(AND(K8="Yes",I8="NOT MET",J8="PARTIALLY IMPLEMENTED"),"Yes","No") | N8: =IF(OR(I8="MET",I8="NOT APPLICABLE",I8="NOT ASSESSED"),0,IF(AND(K8="Yes",J8="PARTIALLY IMPLEMENTED"),3,L8)) | O8: Not Started | S8: =IF(I8="NOT MET","Yes","No") | U8: 32 CFR 170.24(c)(2) | Current eCFR | V8: =IF(I8="MET","Requirement assessed MET; no deduction.",IF(I8="NOT APPLICABLE","Requirement assessed NOT APPLICABLE; no deduction.",IF(I8="NOT ASSESSED","Requirement not assessed; score remains provisional.",IF(M8="Yes","Partial-credit condition applied; 3 points deducted.","Requirement assessed NOT MET; "&L8&" points deducted."))))
A9: AC | B9: AC.L2-3.1.4 | C9: Separation of Duties | D9: Separate the duties of individuals to reduce the risk of malevolent activity without collusion. | E9: 30 | F9: 31 | G9: Yes | H9: ONE_POINT | I9: NOT ASSESSED | K9: No | L9: 1 | M9: =IF(AND(K9="Yes",I9="NOT MET",J9="PARTIALLY IMPLEMENTED"),"Yes","No") | N9: =IF(OR(I9="MET",I9="NOT APPLICABLE",I9="NOT ASSESSED"),0,IF(AND(K9="Yes",J9="PARTIALLY IMPLEMENTED"),3,L9)) | O9: Not Started | S9: =IF(I9="NOT MET","Yes","No") | U9: 32 CFR 170.24(c)(2) | Current eCFR | V9: =IF(I9="MET","Requirement assessed MET; no deduction.",IF(I9="NOT APPLICABLE","Requirement assessed NOT APPLICABLE; no deduction.",IF(I9="NOT ASSESSED","Requirement not assessed; score remains provisional.",IF(M9="Yes","Partial-credit condition applied; 3 points deducted.","Requirement assessed NOT MET; "&L9&" points deducted."))))
A10: AC | B10: AC.L2-3.1.5 | C10: Least Privilege | D10: Employ the principle of least privilege, including for specific security functions and privileged accounts. | E10: 32 | F10: 34 | G10: Yes | H10: THREE_POINT | I10: NOT ASSESSED | K10: No | L10: 3 | M10: =IF(AND(K10="Yes",I10="NOT MET",J10="PARTIALLY IMPLEMENTED"),"Yes","No") | N10: =IF(OR(I10="MET",I10="NOT APPLICABLE",I10="NOT ASSESSED"),0,IF(AND(K10="Yes",J10="PARTIALLY IMPLEMENTED"),3,L10)) | O10: Not Started | S10: =IF(I10="NOT MET","Yes","No") | U10: 32 CFR 170.24(c)(2) | Current eCFR | V10: =IF(I10="MET","Requirement assessed MET; no deduction.",IF(I10="NOT APPLICABLE","Requirement assessed NOT APPLICABLE; no deduction.",IF(I10="NOT ASSESSED","Requirement not assessed; score remains provisional.",IF(M10="Yes","Partial-credit condition applied; 3 points deducted.","Requirement assessed NOT MET; "&L10&" points deducted."))))
A11: AC | B11: AC.L2-3.1.6 | C11: Non-Privileged Account Use | D11: Use non-privileged accounts or roles when accessing nonsecurity functions. | E11: 35 | F11: 36 | G11: Yes | H11: ONE_POINT | I11: NOT ASSESSED | K11: No | L11: 1 | M11: =IF(AND(K11="Yes",I11="NOT MET",J11="PARTIALLY IMPLEMENTED"),"Yes","No") | N11: =IF(OR(I11="MET",I11="NOT APPLICABLE",I11="NOT ASSESSED"),0,IF(AND(K11="Yes",J11="PARTIALLY IMPLEMENTED"),3,L11)) | O11: Not Started | S11: =IF(I11="NOT MET","Yes","No") | U11: 32 CFR 170.24(c)(2) | Current eCFR | V11: =IF(I11="MET","Requirement assessed MET; no deduction.",IF(I11="NOT APPLICABLE","Requirement assessed NOT APPLICABLE; no deduction.",IF(I11="NOT ASSESSED","Requirement not assessed; score remains provisional.",IF(M11="Yes","Partial-credit condition applied; 3 points deducted.","Requirement assessed NOT MET; "&L11&" points deducted."))))
A12: AC | B12: AC.L2-3.1.7 | C12: Privileged Functions | D12: Prevent non-privileged users from executing privileged functions and capture the execution of such functions in audit logs. | E12: 37 | F12: 39 | G12: Yes | H12: ONE_POINT | I12: NOT ASSESSED | K12: No | L12: 1 | M12: =IF(AND(K12="Yes",I12="NOT MET",J12="PARTIALLY IMPLEMENTED"),"Yes","No") | N12: =IF(OR(I12="MET",I12="NOT APPLICABLE",I12="NOT ASSESSED"),0,IF(AND(K12="Yes",J12="PARTIALLY IMPLEMENTED"),3,L12)) | O12: Not Started | S12: =IF(I12="NOT MET","Yes","No") | U12: 32 CFR 170.24(c)(2) | Current eCFR | V12: =IF(I12="MET","Requirement assessed MET; no deduction.",IF(I12="NOT APPLICABLE","Requirement assessed NOT APPLICABLE; no deduction.",IF(I12="NOT ASSESSED","Requirement not assessed; score remains provisional.",IF(M12="Yes","Partial-credit condition applied; 3 points deducted.","Requirement assessed NOT MET; "&L12&" points deducted."))))
A13: AC | B13: AC.L2-3.1.8 | C13: Unsuccessful Logon Attempts | D13: Limit unsuccessful logon attempts. | E13: 40 | F13: 41 | G13: Yes | H13: ONE_POINT | I13: NOT ASSESSED | K13: No | L13: 1 | M13: =IF(AND(K13="Yes",I13="NOT MET",J13="PARTIALLY IMPLEMENTED"),"Yes","No") | N13: =IF(OR(I13="MET",I13="NOT APPLICABLE",I13="NOT ASSESSED"),0,IF(AND(K13="Yes",J13="PARTIALLY IMPLEMENTED"),3,L13)) | O13: Not Started | S13: =IF(I13="NOT MET","Yes","No") | U13: 32 CFR 170.24(c)(2) | Current eCFR | V13: =IF(I13="MET","Requirement assessed MET; no deduction.",IF(I13="NOT APPLICABLE","Requirement assessed NOT APPLICABLE; no deduction.",IF(I13="NOT ASSESSED","Requirement not assessed; score remains provisional.",IF(M13="Yes","Partial-credit condition applied; 3 points deducted.","Requirement assessed NOT MET; "&L13&" points deducted."))))
A14: AC | B14: AC.L2-3.1.9 | C14: Privacy & Security Notices | D14: Provide privacy and security notices consistent with applicable CUI rules. | E14: 42 | F14: 43 | G14: Yes | H14: ONE_POINT | I14: NOT ASSESSED | K14: No | L14: 1 | M14: =IF(AND(K14="Yes",I14="NOT MET",J14="PARTIALLY IMPLEMENTED"),"Yes","No") | N14: =IF(OR(I14="MET",I14="NOT APPLICABLE",I14="NOT ASSESSED"),0,IF(AND(K14="Yes",J14="PARTIALLY IMPLEMENTED"),3,L14)) | O14: Not Started | S14: =IF(I14="NOT MET","Yes","No") | U14: 32 CFR 170.24(c)(2) | Current eCFR | V14: =IF(I14="MET","Requirement assessed MET; no deduction.",IF(I14="NOT APPLICABLE","Requirement assessed NOT APPLICABLE; no deduction.",IF(I14="NOT ASSESSED","Requirement not assessed; score remains provisional.",IF(M14="Yes","Partial-credit condition applied; 3 points deducted.","Requirement assessed NOT MET; "&L14&" points deducted."))))
A15: AC | B15: AC.L2-3.1.10 | C15: Session Lock | D15: Use session lock with pattern- hiding displays to prevent access and viewing of data after a period of inactivity. | E15: 44 | F15: 45 | G15: Yes | H15: ONE_POINT | I15: NOT ASSESSED | K15: No | L15: 1 | M15: =IF(AND(K15="Yes",I15="NOT MET",J15="PARTIALLY IMPLEMENTED"),"Yes","No") | N15: =IF(OR(I15="MET",I15="NOT APPLICABLE",I15="NOT ASSESSED"),0,IF(AND(K15="Yes",J15="PARTIALLY IMPLEMENTED"),3,L15)) | O15: Not Started | S15: =IF(I15="NOT MET","Yes","No") | U15: 32 CFR 170.24(c)(2) | Current eCFR | V15: =IF(I15="MET","Requirement assessed MET; no deduction.",IF(I15="NOT APPLICABLE","Requirement assessed NOT APPLICABLE; no deduction.",IF(I15="NOT ASSESSED","Requirement not assessed; score remains provisional.",IF(M15="Yes","Partial-credit condition applied; 3 points deducted.","Requirement assessed NOT MET; "&L15&" points deducted."))))
A16: AC | B16: AC.L2-3.1.11 | C16: Session Termination | D16: Terminate (automatically) a user session after a defined condition. | E16: 46 | F16: 47 | G16: Yes | H16: ONE_POINT | I16: NOT ASSESSED | K16: No | L16: 1 | M16: =IF(AND(K16="Yes",I16="NOT MET",J16="PARTIALLY IMPLEMENTED"),"Yes","No") | N16: =IF(OR(I16="MET",I16="NOT APPLICABLE",I16="NOT ASSESSED"),0,IF(AND(K16="Yes",J16="PARTIALLY IMPLEMENTED"),3,L16)) | O16: Not Started | S16: =IF(I16="NOT MET","Yes","No") | U16: 32 CFR 170.24(c)(2) | Current eCFR | V16: =IF(I16="MET","Requirement assessed MET; no deduction.",IF(I16="NOT APPLICABLE","Requirement assessed NOT APPLICABLE; no deduction.",IF(I16="NOT ASSESSED","Requirement not assessed; score remains provisional.",IF(M16="Yes","Partial-credit condition applied; 3 points deducted.","Requirement assessed NOT MET; "&L16&" points deducted."))))
A17: AC | B17: AC.L2-3.1.12 | C17: Control Remote Access | D17: Monitor and control remote access sessions. | E17: 48 | F17: 50 | G17: Yes | H17: FIVE_POINT | I17: NOT ASSESSED | K17: No | L17: 5 | M17: =IF(AND(K17="Yes",I17="NOT MET",J17="PARTIALLY IMPLEMENTED"),"Yes","No") | N17: =IF(OR(I17="MET",I17="NOT APPLICABLE",I17="NOT ASSESSED"),0,IF(AND(K17="Yes",J17="PARTIALLY IMPLEMENTED"),3,L17)) | O17: Not Started | S17: =IF(I17="NOT MET","Yes","No") | U17: 32 CFR 170.24(c)(2) | Current eCFR | V17: =IF(I17="MET","Requirement assessed MET; no deduction.",IF(I17="NOT APPLICABLE","Requirement assessed NOT APPLICABLE; no deduction.",IF(I17="NOT ASSESSED","Requirement not assessed; score remains provisional.",IF(M17="Yes","Partial-credit condition applied; 3 points deducted.","Requirement assessed NOT MET; "&L17&" points deducted."))))
... A50: IA | B50: IA.L2-3.5.2 | C50: Authentication [CUI Data] | D50: Authenticate (or verify) the identities of users, processes, or devices, as a prerequisite to allowing access to organizational systems. | E50: 122 | F50: 124 | G50: Yes | H50: FIVE_POINT | I50: NOT ASSESSED | K50: No | L50: 5 | M50: =IF(AND(K50="Yes",I50="NOT MET",J50="PARTIALLY IMPLEMENTED"),"Yes","No") | N50: =IF(OR(I50="MET",I50="NOT APPLICABLE",I50="NOT ASSESSED"),0,IF(AND(K50="Yes",J50="PARTIALLY IMPLEMENTED"),3,L50)) | O50: Not Started | S50: =IF(I50="NOT MET","Yes","No") | U50: 32 CFR 170.24(c)(2) | Current eCFR | V50: =IF(I50="MET","Requirement assessed MET; no deduction.",IF(I50="NOT APPLICABLE","Requirement assessed NOT APPLICABLE; no deduction.",IF(I50="NOT ASSESSED","Requirement not assessed; score remains provisional.",IF(M50="Yes","Partial-credit condition applied; 3 points deducted.","Requirement assessed NOT MET; "&L50&" points deducted."))))
A51: IA | B51: IA.L2-3.5.3 | C51: Multifactor Authentication | D51: Use multifactor authentication for local and network access to privileged accounts and for network access to non-privileged accounts. | E51: 125 | F51: 127 | G51: Yes | H51: PARTIAL_3_OR_5 | I51: NOT ASSESSED | J51: NOT ASSESSED | K51: Yes | L51: 5 | M51: =IF(AND(K51="Yes",I51="NOT MET",J51="PARTIALLY IMPLEMENTED"),"Yes","No") | N51: =IF(OR(I51="MET",I51="NOT APPLICABLE",I51="NOT ASSESSED"),0,IF(AND(K51="Yes",J51="PARTIALLY IMPLEMENTED"),3,L51)) | O51: Not Started | S51: =IF(I51="NOT MET","Yes","No") | T51: MFA is implemented only for remote and privileged users. | U51: 32 CFR 170.24(c)(2) | Current eCFR | V51: =IF(I51="MET","Requirement assessed MET; no deduction.",IF(I51="NOT APPLICABLE","Requirement assessed NOT APPLICABLE; no deduction.",IF(I51="NOT ASSESSED","Requirement not assessed; score remains provisional.",IF(M51="Yes","Partial-credit condition applied; 3 points deducted.","Requirement assessed NOT MET; "&L51&" points deducted."))))
A52: IA | B52: IA.L2-3.5.4 | C52: Replay-Resistant Authentication | D52: Employ replay -resistant authentication mechanisms for network access to privileged and non-privileged accounts. | E52: 128 | F52: 129 | G52: Yes | H52: ONE_POINT | I52: NOT ASSESSED | K52: No | L52: 1 | M52: =IF(AND(K52="Yes",I52="NOT MET",J52="PARTIALLY IMPLEMENTED"),"Yes","No") | N52: =IF(OR(I52="MET",I52="NOT APPLICABLE",I52="NOT ASSESSED"),0,IF(AND(K52="Yes",J52="PARTIALLY IMPLEMENTED"),3,L52)) | O52: Not Started | S52: =IF(I52="NOT MET","Yes","No") | U52: 32 CFR 170.24(c)(2) | Current eCFR | V52: =IF(I52="MET","Requirement assessed MET; no deduction.",IF(I52="NOT APPLICABLE","Requirement assessed NOT APPLICABLE; no deduction.",IF(I52="NOT ASSESSED","Requirement not assessed; score remains provisional.",IF(M52="Yes","Partial-credit condition applied; 3 points deducted.","Requirement assessed NOT MET; "&L52&" points deducted."))))
A53: IA | B53: IA.L2-3.5.5 | C53: Identifier Reuse | D53: Prevent reuse of identifiers for a defined period. | E53: 130 | F53: 131 | G53: Yes | H53: ONE_POINT | I53: NOT ASSESSED | K53: No | L53: 1 | M53: =IF(AND(K53="Yes",I53="NOT MET",J53="PARTIALLY IMPLEMENTED"),"Yes","No") | N53: =IF(OR(I53="MET",I53="NOT APPLICABLE",I53="NOT ASSESSED"),0,IF(AND(K53="Yes",J53="PARTIALLY IMPLEMENTED"),3,L53)) | O53: Not Started | S53: =IF(I53="NOT MET","Yes","No") | U53: 32 CFR 170.24(c)(2) | Current eCFR | V53: =IF(I53="MET","Requirement assessed MET; no deduction.",IF(I53="NOT APPLICABLE","Requirement assessed NOT APPLICABLE; no deduction.",IF(I53="NOT ASSESSED","Requirement not assessed; score remains provisional.",IF(M53="Yes","Partial-credit condition applied; 3 points deducted.","Requirement assessed NOT MET; "&L53&" points deducted."))))
A54: IA | B54: IA.L2-3.5.6 | C54: Identifier Handling | D54: Disable identifiers after a defined period of inactivity. | E54: 132 | F54: 133 | G54: Yes | H54: ONE_POINT | I54: NOT ASSESSED | K54: No | L54: 1 | M54: =IF(AND(K54="Yes",I54="NOT MET",J54="PARTIALLY IMPLEMENTED"),"Yes","No") | N54: =IF(OR(I54="MET",I54="NOT APPLICABLE",I54="NOT ASSESSED"),0,IF(AND(K54="Yes",J54="PARTIALLY IMPLEMENTED"),3,L54)) | O54: Not Started | S54: =IF(I54="NOT MET","Yes","No") | U54: 32 CFR 170.24(c)(2) | Current eCFR | V54: =IF(I54="MET","Requirement assessed MET; no deduction.",IF(I54="NOT APPLICABLE","Requirement assessed NOT APPLICABLE; no deduction.",IF(I54="NOT ASSESSED","Requirement not assessed; score remains provisional.",IF(M54="Yes","Partial-credit condition applied; 3 points deducted.","Requirement assessed NOT MET; "&L54&" points deducted."))))
A55: IA | B55: IA.L2-3.5.7 | C55: Password Complexity | D55: Enforce a minimum password complexity and change of characters when new passwords are created. | E55: 134 | F55: 135 | G55: Yes | H55: ONE_POINT | I55: NOT ASSESSED | K55: No | L55: 1 | M55: =IF(AND(K55="Yes",I55="NOT MET",J55="PARTIALLY IMPLEMENTED"),"Yes","No") | N55: =IF(OR(I55="MET",I55="NOT APPLICABLE",I55="NOT ASSESSED"),0,IF(AND(K55="Yes",J55="PARTIALLY IMPLEMENTED"),3,L55)) | O55: Not Started | S55: =IF(I55="NOT MET","Yes","No") | U55: 32 CFR 170.24(c)(2) | Current eCFR | V55: =IF(I55="MET","Requirement assessed MET; no deduction.",IF(I55="NOT APPLICABLE","Requirement assessed NOT APPLICABLE; no deduction.",IF(I55="NOT ASSESSED","Requirement not assessed; score remains provisional.",IF(M55="Yes","Partial-credit condition applied; 3 points deducted.","Requirement assessed NOT MET; "&L55&" points deducted."))))
A56: IA | B56: IA.L2-3.5.8 | C56: Password Reuse | D56: Prohibit password reuse for a specified number of generations. | E56: 136 | F56: 137 | G56: Yes | H56: ONE_POINT | I56: NOT ASSESSED | K56: No | L56: 1 | M56: =IF(AND(K56="Yes",I56="NOT MET",J56="PARTIALLY IMPLEMENTED"),"Yes","No") | N56: =IF(OR(I56="MET",I56="NOT APPLICABLE",I56="NOT ASSESSED"),0,IF(AND(K56="Yes",J56="PARTIALLY IMPLEMENTED"),3,L56)) | O56: Not Started | S56: =IF(I56="NOT MET","Yes","No") | U56: 32 CFR 170.24(c)(2) | Current eCFR | V56: =IF(I56="MET","Requirement assessed MET; no deduction.",IF(I56="NOT APPLICABLE","Requirement assessed NOT APPLICABLE; no deduction.",IF(I56="NOT ASSESSED","Requirement not assessed; score remains provisional.",IF(M56="Yes","Partial-credit condition applied; 3 points deducted.","Requirement assessed NOT MET; "&L56&" points deducted."))))
A57: IA | B57: IA.L2-3.5.9 | C57: Temporary Passwords | D57: Allow temporary password use for system logons with an immediate change to a permanent password. | E57: 138 | F57: 139 | G57: Yes | H57: ONE_POINT | I57: NOT ASSESSED | K57: No | L57: 1 | M57: =IF(AND(K57="Yes",I57="NOT MET",J57="PARTIALLY IMPLEMENTED"),"Yes","No") | N57: =IF(OR(I57="MET",I57="NOT APPLICABLE",I57="NOT ASSESSED"),0,IF(AND(K57="Yes",J57="PARTIALLY IMPLEMENTED"),3,L57)) | O57: Not Started | S57: =IF(I57="NOT MET","Yes","No") | U57: 32 CFR 170.24(c)(2) | Current eCFR | V57: =IF(I57="MET","Requirement assessed MET; no deduction.",IF(I57="NOT APPLICABLE","Requirement assessed NOT APPLICABLE; no deduction.",IF(I57="NOT ASSESSED","Requirement not assessed; score remains provisional.",IF(M57="Yes","Partial-credit condition applied; 3 points deducted.","Requirement assessed NOT MET; "&L57&" points deducted."))))
A58: IA | B58: IA.L2-3.5.10 | C58: Cryptographically-Protected Passwords | D58: Store and transmit only cryptographically-protected passwords. | E58: 140 | F58: 141 | G58: Yes | H58: FIVE_POINT | I58: NOT ASSESSED | K58: No | L58: 5 | M58: =IF(AND(K58="Yes",I58="NOT MET",J58="PARTIALLY IMPLEMENTED"),"Yes","No") | N58: =IF(OR(I58="MET",I58="NOT APPLICABLE",I58="NOT ASSESSED"),0,IF(AND(K58="Yes",J58="PARTIALLY IMPLEMENTED"),3,L58)) | O58: Not Started | S58: =IF(I58="NOT MET","Yes","No") | U58: 32 CFR 170.24(c)(2) | Current eCFR | V58: =IF(I58="MET","Requirement assessed MET; no deduction.",IF(I58="NOT APPLICABLE","Requirement assessed NOT APPLICABLE; no deduction.",IF(I58="NOT ASSESSED","Requirement not assessed; score remains provisional.",IF(M58="Yes","Partial-credit condition applied; 3 points deducted.","Requirement assessed NOT MET; "&L58&" points deducted."))))
A59: IA | B59: IA.L2-3.5.11 | C59: Obscure Feedback | D59: Obscure feedback of authentication information. | E59: 142 | F59: 143 | G59: Yes | H59: ONE_POINT | I59: NOT ASSESSED | K59: No | L59: 1 | M59: =IF(AND(K59="Yes",I59="NOT MET",J59="PARTIALLY IMPLEMENTED"),"Yes","No") | N59: =IF(OR(I59="MET",I59="NOT APPLICABLE",I59="NOT ASSESSED"),0,IF(AND(K59="Yes",J59="PARTIALLY IMPLEMENTED"),3,L59)) | O59: Not Started | S59: =IF(I59="NOT MET","Yes","No") | U59: 32 CFR 170.24(c)(2) | Current eCFR | V59: =IF(I59="MET","Requirement assessed MET; no deduction.",IF(I59="NOT APPLICABLE","Requirement assessed NOT APPLICABLE; no deduction.",IF(I59="NOT ASSESSED","Requirement not assessed; score remains provisional.",IF(M59="Yes","Partial-credit condition applied; 3 points deducted.","Requirement assessed NOT MET; "&L59&" points deducted."))))
A60: IR | B60: IR.L2-3.6.1 | C60: Incident Handling | D60: Establish an operational incident-handling capability for organizational systems that includes preparation, detection, analysis, containment, recovery, and user response activities. | E60: 144 | F60: 146 | G60: Yes | H60: FIVE_POINT | I60: NOT ASSESSED | K60: No | L60: 5 | M60: =IF(AND(K60="Yes",I60="NOT MET",J60="PARTIALLY IMPLEMENTED"),"Yes","No") | N60: =IF(OR(I60="MET",I60="NOT APPLICABLE",I60="NOT ASSESSED"),0,IF(AND(K60="Yes",J60="PARTIALLY IMPLEMENTED"),3,L60)) | O60: Not Started | S60: =IF(I60="NOT MET","Yes","No") | U60: 32 CFR 170.24(c)(2) | Current eCFR | V60: =IF(I60="MET","Requirement assessed MET; no deduction.",IF(I60="NOT APPLICABLE","Requirement assessed NOT APPLICABLE; no deduction.",IF(I60="NOT ASSESSED","Requirement not assessed; score remains provisional.",IF(M60="Yes","Partial-credit condition applied; 3 points deducted.","Requirement assessed NOT MET; "&L60&" points deducted."))))
A61: IR | B61: IR.L2-3.6.2 | C61: Incident Reporting | D61: Track, document, and report incidents to designated officials and/or authorities both internal and external to the organization. | E61: 147 | F61: 149 | G61: Yes | H61: FIVE_POINT | I61: NOT ASSESSED | K61: No | L61: 5 | M61: =IF(AND(K61="Yes",I61="NOT MET",J61="PARTIALLY IMPLEMENTED"),"Yes","No") | N61: =IF(OR(I61="MET",I61="NOT APPLICABLE",I61="NOT ASSESSED"),0,IF(AND(K61="Yes",J61="PARTIALLY IMPLEMENTED"),3,L61)) | O61: Not Started | S61: =IF(I61="NOT MET","Yes","No") | U61: 32 CFR 170.24(c)(2) | Current eCFR | V61: =IF(I61="MET","Requirement assessed MET; no deduction.",IF(I61="NOT APPLICABLE","Requirement assessed NOT APPLICABLE; no deduction.",IF(I61="NOT ASSESSED","Requirement not assessed; score remains provisional.",IF(M61="Yes","Partial-credit condition applied; 3 points deducted.","Requirement assessed NOT MET; "&L61&" points deducted."))))
A62: IR | B62: IR.L2-3.6.3 | C62: Incident Response Testing | D62: Test the organizational incident response capability. | E62: 150 | F62: 151 | G62: Yes | H62: ONE_POINT | I62: NOT ASSESSED | K62: No | L62: 1 | M62: =IF(AND(K62="Yes",I62="NOT MET",J62="PARTIALLY IMPLEMENTED"),"Yes","No") | N62: =IF(OR(I62="MET",I62="NOT APPLICABLE",I62="NOT ASSESSED"),0,IF(AND(K62="Yes",J62="PARTIALLY IMPLEMENTED"),3,L62)) | O62: Not Started | S62: =IF(I62="NOT MET","Yes","No") | U62: 32 CFR 170.24(c)(2) | Current eCFR | V62: =IF(I62="MET","Requirement assessed MET; no deduction.",IF(I62="NOT APPLICABLE","Requirement assessed NOT APPLICABLE; no deduction.",IF(I62="NOT ASSESSED","Requirement not assessed; score remains provisional.",IF(M62="Yes","Partial-credit condition applied; 3 points deducted.","Requirement assessed NOT MET; "&L62&" points deducted."))))
A63: MA | B63: MA.L2-3.7.1 | C63: Perform Maintenance | D63: Perform maintenance on organizational systems. | E63: 152 | F63: 153 | G63: Yes | H63: THREE_POINT | I63: NOT ASSESSED | K63: No | L63: 3 | M63: =IF(AND(K63="Yes",I63="NOT MET",J63="PARTIALLY IMPLEMENTED"),"Yes","No") | N63: =IF(OR(I63="MET",I63="NOT APPLICABLE",I63="NOT ASSESSED"),0,IF(AND(K63="Yes",J63="PARTIALLY IMPLEMENTED"),3,L63)) | O63: Not Started | S63: =IF(I63="NOT MET","Yes","No") | U63: 32 CFR 170.24(c)(2) | Current eCFR | V63: =IF(I63="MET","Requirement assessed MET; no deduction.",IF(I63="NOT APPLICABLE","Requirement assessed NOT APPLICABLE; no deduction.",IF(I63="NOT ASSESSED","Requirement not assessed; score remains provisional.",IF(M63="Yes","Partial-credit condition applied; 3 points deducted.","Requirement assessed NOT MET; "&L63&" points deducted."))))
... A102: SC | B102: SC.L2-3.13.10 | C102: Key Management | D102: Establish and manage cryptographic keys for cryptography employed in organizational systems. | E102: 239 | F102: 241 | G102: Yes | H102: ONE_POINT | I102: NOT ASSESSED | K102: No | L102: 1 | M102: =IF(AND(K102="Yes",I102="NOT MET",J102="PARTIALLY IMPLEMENTED"),"Yes","No") | N102: =IF(OR(I102="MET",I102="NOT APPLICABLE",I102="NOT ASSESSED"),0,IF(AND(K102="Yes",J102="PARTIALLY IMPLEMENTED"),3,L102)) | O102: Not Started | S102: =IF(I102="NOT MET","Yes","No") | U102: 32 CFR 170.24(c)(2) | Current eCFR | V102: =IF(I102="MET","Requirement assessed MET; no deduction.",IF(I102="NOT APPLICABLE","Requirement assessed NOT APPLICABLE; no deduction.",IF(I102="NOT ASSESSED","Requirement not assessed; score remains provisional.",IF(M102="Yes","Partial-credit condition applied; 3 points deducted.","Requirement assessed NOT MET; "&L102&" points deducted."))))
A103: SC | B103: SC.L2-3.13.11 | C103: CUI Encryption | D103: Employ FIPS-validated cryptography when used to protect the confidentiality of CUI. | E103: 242 | F103: 243 | G103: Yes | H103: PARTIAL_3_OR_5 | I103: NOT ASSESSED | J103: NOT ASSESSED | K103: Yes | L103: 5 | M103: =IF(AND(K103="Yes",I103="NOT MET",J103="PARTIALLY IMPLEMENTED"),"Yes","No") | N103: =IF(OR(I103="MET",I103="NOT APPLICABLE",I103="NOT ASSESSED"),0,IF(AND(K103="Yes",J103="PARTIALLY IMPLEMENTED"),3,L103)) | O103: Not Started | S103: =IF(I103="NOT MET","Yes","No") | T103: Encryption is employed, but it is not FIPS-validated. | U103: 32 CFR 170.24(c)(2) | Current eCFR | V103: =IF(I103="MET","Requirement assessed MET; no deduction.",IF(I103="NOT APPLICABLE","Requirement assessed NOT APPLICABLE; no deduction.",IF(I103="NOT ASSESSED","Requirement not assessed; score remains provisional.",IF(M103="Yes","Partial-credit condition applied; 3 points deducted.","Requirement assessed NOT MET; "&L103&" points deducted."))))
A104: SC | B104: SC.L2-3.13.12 | C104: Collaborative Device Control | D104: Prohibit remote activation of collaborative computing devices and provide indication of devices in use to users present at the device. | E104: 244 | F104: 245 | G104: Yes | H104: ONE_POINT | I104: NOT ASSESSED | K104: No | L104: 1 | M104: =IF(AND(K104="Yes",I104="NOT MET",J104="PARTIALLY IMPLEMENTED"),"Yes","No") | N104: =IF(OR(I104="MET",I104="NOT APPLICABLE",I104="NOT ASSESSED"),0,IF(AND(K104="Yes",J104="PARTIALLY IMPLEMENTED"),3,L104)) | O104: Not Started | S104: =IF(I104="NOT MET","Yes","No") | U104: 32 CFR 170.24(c)(2) | Current eCFR | V104: =IF(I104="MET","Requirement assessed MET; no deduction.",IF(I104="NOT APPLICABLE","Requirement assessed NOT APPLICABLE; no deduction.",IF(I104="NOT ASSESSED","Requirement not assessed; score remains provisional.",IF(M104="Yes","Partial-credit condition applied; 3 points deducted.","Requirement assessed NOT MET; "&L104&" points deducted."))))
A105: SC | B105: SC.L2-3.13.13 | C105: Mobile Code | D105: Control and monitor the use of mobile code. | E105: 246 | F105: 247 | G105: Yes | H105: ONE_POINT | I105: NOT ASSESSED | K105: No | L105: 1 | M105: =IF(AND(K105="Yes",I105="NOT MET",J105="PARTIALLY IMPLEMENTED"),"Yes","No") | N105: =IF(OR(I105="MET",I105="NOT APPLICABLE",I105="NOT ASSESSED"),0,IF(AND(K105="Yes",J105="PARTIALLY IMPLEMENTED"),3,L105)) | O105: Not Started | S105: =IF(I105="NOT MET","Yes","No") | U105: 32 CFR 170.24(c)(2) | Current eCFR | V105: =IF(I105="MET","Requirement assessed MET; no deduction.",IF(I105="NOT APPLICABLE","Requirement assessed NOT APPLICABLE; no deduction.",IF(I105="NOT ASSESSED","Requirement not assessed; score remains provisional.",IF(M105="Yes","Partial-credit condition applied; 3 points deducted.","Requirement assessed NOT MET; "&L105&" points deducted."))))
A106: SC | B106: SC.L2-3.13.14 | C106: Voice over Internet Protocol | D106: Control and monitor the use of Voice over Internet Protocol (VoIP) technologies. | E106: 248 | F106: 249 | G106: Yes | H106: ONE_POINT | I106: NOT ASSESSED | K106: No | L106: 1 | M106: =IF(AND(K106="Yes",I106="NOT MET",J106="PARTIALLY IMPLEMENTED"),"Yes","No") | N106: =IF(OR(I106="MET",I106="NOT APPLICABLE",I106="NOT ASSESSED"),0,IF(AND(K106="Yes",J106="PARTIALLY IMPLEMENTED"),3,L106)) | O106: Not Started | S106: =IF(I106="NOT MET","Yes","No") | U106: 32 CFR 170.24(c)(2) | Current eCFR | V106: =IF(I106="MET","Requirement assessed MET; no deduction.",IF(I106="NOT APPLICABLE","Requirement assessed NOT APPLICABLE; no deduction.",IF(I106="NOT ASSESSED","Requirement not assessed; score remains provisional.",IF(M106="Yes","Partial-credit condition applied; 3 points deducted.","Requirement assessed NOT MET; "&L106&" points deducted."))))
A107: SC | B107: SC.L2-3.13.15 | C107: Communications Authenticity | D107: Protect the authenticity of communications sessions. | E107: 250 | F107: 251 | G107: Yes | H107: FIVE_POINT | I107: NOT ASSESSED | K107: No | L107: 5 | M107: =IF(AND(K107="Yes",I107="NOT MET",J107="PARTIALLY IMPLEMENTED"),"Yes","No") | N107: =IF(OR(I107="MET",I107="NOT APPLICABLE",I107="NOT ASSESSED"),0,IF(AND(K107="Yes",J107="PARTIALLY IMPLEMENTED"),3,L107)) | O107: Not Started | S107: =IF(I107="NOT MET","Yes","No") | U107: 32 CFR 170.24(c)(2) | Current eCFR | V107: =IF(I107="MET","Requirement assessed MET; no deduction.",IF(I107="NOT APPLICABLE","Requirement assessed NOT APPLICABLE; no deduction.",IF(I107="NOT ASSESSED","Requirement not assessed; score remains provisional.",IF(M107="Yes","Partial-credit condition applied; 3 points deducted.","Requirement assessed NOT MET; "&L107&" points deducted."))))
A108: SC | B108: SC.L2-3.13.16 | C108: Data at Rest | D108: Protect the confidentiality of CUI at rest. | E108: 252 | F108: 253 | G108: Yes | H108: ONE_POINT | I108: NOT ASSESSED | K108: No | L108: 1 | M108: =IF(AND(K108="Yes",I108="NOT MET",J108="PARTIALLY IMPLEMENTED"),"Yes","No") | N108: =IF(OR(I108="MET",I108="NOT APPLICABLE",I108="NOT ASSESSED"),0,IF(AND(K108="Yes",J108="PARTIALLY IMPLEMENTED"),3,L108)) | O108: Not Started | S108: =IF(I108="NOT MET","Yes","No") | U108: 32 CFR 170.24(c)(2) | Current eCFR | V108: =IF(I108="MET","Requirement assessed MET; no deduction.",IF(I108="NOT APPLICABLE","Requirement assessed NOT APPLICABLE; no deduction.",IF(I108="NOT ASSESSED","Requirement not assessed; score remains provisional.",IF(M108="Yes","Partial-credit condition applied; 3 points deducted.","Requirement assessed NOT MET; "&L108&" points deducted."))))
A109: SI | B109: SI.L2-3.14.1 | C109: Flaw Remediation [CUI Data] | D109: Identify, report, and correct system flaws in a timely manner. | E109: 254 | F109: 256 | G109: Yes | H109: FIVE_POINT | I109: NOT ASSESSED | K109: No | L109: 5 | M109: =IF(AND(K109="Yes",I109="NOT MET",J109="PARTIALLY IMPLEMENTED"),"Yes","No") | N109: =IF(OR(I109="MET",I109="NOT APPLICABLE",I109="NOT ASSESSED"),0,IF(AND(K109="Yes",J109="PARTIALLY IMPLEMENTED"),3,L109)) | O109: Not Started | S109: =IF(I109="NOT MET","Yes","No") | U109: 32 CFR 170.24(c)(2) | Current eCFR | V109: =IF(I109="MET","Requirement assessed MET; no deduction.",IF(I109="NOT APPLICABLE","Requirement assessed NOT APPLICABLE; no deduction.",IF(I109="NOT ASSESSED","Requirement not assessed; score remains provisional.",IF(M109="Yes","Partial-credit condition applied; 3 points deducted.","Requirement assessed NOT MET; "&L109&" points deducted."))))
A110: SI | B110: SI.L2-3.14.2 | C110: Malicious Code Protection [CUI Data] | D110: Provide protection from malicious code at designated locations within organizational systems. | E110: 257 | F110: 259 | G110: Yes | H110: FIVE_POINT | I110: NOT ASSESSED | K110: No | L110: 5 | M110: =IF(AND(K110="Yes",I110="NOT MET",J110="PARTIALLY IMPLEMENTED"),"Yes","No") | N110: =IF(OR(I110="MET",I110="NOT APPLICABLE",I110="NOT ASSESSED"),0,IF(AND(K110="Yes",J110="PARTIALLY IMPLEMENTED"),3,L110)) | O110: Not Started | S110: =IF(I110="NOT MET","Yes","No") | U110: 32 CFR 170.24(c)(2) | Current eCFR | V110: =IF(I110="MET","Requirement assessed MET; no deduction.",IF(I110="NOT APPLICABLE","Requirement assessed NOT APPLICABLE; no deduction.",IF(I110="NOT ASSESSED","Requirement not assessed; score remains provisional.",IF(M110="Yes","Partial-credit condition applied; 3 points deducted.","Requirement assessed NOT MET; "&L110&" points deducted."))))
A111: SI | B111: SI.L2-3.14.3 | C111: Security Alerts & Advisories | D111: Monitor system security alerts and advisories and take action in response. | E111: 260 | F111: 261 | G111: Yes | H111: FIVE_POINT | I111: NOT ASSESSED | K111: No | L111: 5 | M111: =IF(AND(K111="Yes",I111="NOT MET",J111="PARTIALLY IMPLEMENTED"),"Yes","No") | N111: =IF(OR(I111="MET",I111="NOT APPLICABLE",I111="NOT ASSESSED"),0,IF(AND(K111="Yes",J111="PARTIALLY IMPLEMENTED"),3,L111)) | O111: Not Started | S111: =IF(I111="NOT MET","Yes","No") | U111: 32 CFR 170.24(c)(2) | Current eCFR | V111: =IF(I111="MET","Requirement assessed MET; no deduction.",IF(I111="NOT APPLICABLE","Requirement assessed NOT APPLICABLE; no deduction.",IF(I111="NOT ASSESSED","Requirement not assessed; score remains provisional.",IF(M111="Yes","Partial-credit condition applied; 3 points deducted.","Requirement assessed NOT MET; "&L111&" points deducted."))))
A112: SI | B112: SI.L2-3.14.4 | C112: Update Malicious Code Protection [CUI Data] | D112: Update malicious code protection mechanisms when new releases are available. | E112: 262 | F112: 263 | G112: Yes | H112: FIVE_POINT | I112: NOT ASSESSED | K112: No | L112: 5 | M112: =IF(AND(K112="Yes",I112="NOT MET",J112="PARTIALLY IMPLEMENTED"),"Yes","No") | N112: =IF(OR(I112="MET",I112="NOT APPLICABLE",I112="NOT ASSESSED"),0,IF(AND(K112="Yes",J112="PARTIALLY IMPLEMENTED"),3,L112)) | O112: Not Started | S112: =IF(I112="NOT MET","Yes","No") | U112: 32 CFR 170.24(c)(2) | Current eCFR | V112: =IF(I112="MET","Requirement assessed MET; no deduction.",IF(I112="NOT APPLICABLE","Requirement assessed NOT APPLICABLE; no deduction.",IF(I112="NOT ASSESSED","Requirement not assessed; score remains provisional.",IF(M112="Yes","Partial-credit condition applied; 3 points deducted.","Requirement assessed NOT MET; "&L112&" points deducted."))))
...

Sheet Domain Summary
A1: Domain Summary
A3: Weighted scoring, completion, and findings by CMMC domain
A5: Domain | B5: Requirement Count | C5: Met | D5: Not Met | E5: Not Assessed | F5: Full Weight | G5: Current Deduction | H5: Completion % | I5: Domain Score | J5: Readiness
A6: AC | B6: =COUNTIF(Assessment!$A$6:$A$115,A6) | C6: =COUNTIFS(Assessment!$A$6:$A$115,A6,Assessment!$I$6:$I$115,"MET") | D6: =COUNTIFS(Assessment!$A$6:$A$115,A6,Assessment!$I$6:$I$115,"NOT MET") | E6: =COUNTIFS(Assessment!$A$6:$A$115,A6,Assessment!$I$6:$I$115,"NOT ASSESSED") | F6: =SUMIF(Assessment!$A$6:$A$115,A6,Assessment!$L$6:$L$115) | G6: =SUMIF(Assessment!$A$6:$A$115,A6,Assessment!$N$6:$N$115) | H6: =IF(B6=0,0,(B6-E6)/B6) | I6: =F6-G6 | J6: =IF(E6>0,"INCOMPLETE",IF(D6=0,"READY","NEEDS WORK"))
A7: AT | B7: =COUNTIF(Assessment!$A$6:$A$115,A7) | C7: =COUNTIFS(Assessment!$A$6:$A$115,A7,Assessment!$I$6:$I$115,"MET") | D7: =COUNTIFS(Assessment!$A$6:$A$115,A7,Assessment!$I$6:$I$115,"NOT MET") | E7: =COUNTIFS(Assessment!$A$6:$A$115,A7,Assessment!$I$6:$I$115,"NOT ASSESSED") | F7: =SUMIF(Assessment!$A$6:$A$115,A7,Assessment!$L$6:$L$115) | G7: =SUMIF(Assessment!$A$6:$A$115,A7,Assessment!$N$6:$N$115) | H7: =IF(B7=0,0,(B7-E7)/B7) | I7: =F7-G7 | J7: =IF(E7>0,"INCOMPLETE",IF(D7=0,"READY","NEEDS WORK"))
A8: AU | B8: =COUNTIF(Assessment!$A$6:$A$115,A8) | C8: =COUNTIFS(Assessment!$A$6:$A$115,A8,Assessment!$I$6:$I$115,"MET") | D8: =COUNTIFS(Assessment!$A$6:$A$115,A8,Assessment!$I$6:$I$115,"NOT MET") | E8: =COUNTIFS(Assessment!$A$6:$A$115,A8,Assessment!$I$6:$I$115,"NOT ASSESSED") | F8: =SUMIF(Assessment!$A$6:$A$115,A8,Assessment!$L$6:$L$115) | G8: =SUMIF(Assessment!$A$6:$A$115,A8,Assessment!$N$6:$N$115) | H8: =IF(B8=0,0,(B8-E8)/B8) | I8: =F8-G8 | J8: =IF(E8>0,"INCOMPLETE",IF(D8=0,"READY","NEEDS WORK"))
A9: CM | B9: =COUNTIF(Assessment!$A$6:$A$115,A9) | C9: =COUNTIFS(Assessment!$A$6:$A$115,A9,Assessment!$I$6:$I$115,"MET") | D9: =COUNTIFS(Assessment!$A$6:$A$115,A9,Assessment!$I$6:$I$115,"NOT MET") | E9: =COUNTIFS(Assessment!$A$6:$A$115,A9,Assessment!$I$6:$I$115,"NOT ASSESSED") | F9: =SUMIF(Assessment!$A$6:$A$115,A9,Assessment!$L$6:$L$115) | G9: =SUMIF(Assessment!$A$6:$A$115,A9,Assessment!$N$6:$N$115) | H9: =IF(B9=0,0,(B9-E9)/B9) | I9: =F9-G9 | J9: =IF(E9>0,"INCOMPLETE",IF(D9=0,"READY","NEEDS WORK"))
A10: IA | B10: =COUNTIF(Assessment!$A$6:$A$115,A10) | C10: =COUNTIFS(Assessment!$A$6:$A$115,A10,Assessment!$I$6:$I$115,"MET") | D10: =COUNTIFS(Assessment!$A$6:$A$115,A10,Assessment!$I$6:$I$115,"NOT MET") | E10: =COUNTIFS(Assessment!$A$6:$A$115,A10,Assessment!$I$6:$I$115,"NOT ASSESSED") | F10: =SUMIF(Assessment!$A$6:$A$115,A10,Assessment!$L$6:$L$115) | G10: =SUMIF(Assessment!$A$6:$A$115,A10,Assessment!$N$6:$N$115) | H10: =IF(B10=0,0,(B10-E10)/B10) | I10: =F10-G10 | J10: =IF(E10>0,"INCOMPLETE",IF(D10=0,"READY","NEEDS WORK"))
A11: IR | B11: =COUNTIF(Assessment!$A$6:$A$115,A11) | C11: =COUNTIFS(Assessment!$A$6:$A$115,A11,Assessment!$I$6:$I$115,"MET") | D11: =COUNTIFS(Assessment!$A$6:$A$115,A11,Assessment!$I$6:$I$115,"NOT MET") | E11: =COUNTIFS(Assessment!$A$6:$A$115,A11,Assessment!$I$6:$I$115,"NOT ASSESSED") | F11: =SUMIF(Assessment!$A$6:$A$115,A11,Assessment!$L$6:$L$115) | G11: =SUMIF(Assessment!$A$6:$A$115,A11,Assessment!$N$6:$N$115) | H11: =IF(B11=0,0,(B11-E11)/B11) | I11: =F11-G11 | J11: =IF(E11>0,"INCOMPLETE",IF(D11=0,"READY","NEEDS WORK"))
A12: MA | B12: =COUNTIF(Assessment!$A$6:$A$115,A12) | C12: =COUNTIFS(Assessment!$A$6:$A$115,A12,Assessment!$I$6:$I$115,"MET") | D12: =COUNTIFS(Assessment!$A$6:$A$115,A12,Assessment!$I$6:$I$115,"NOT MET") | E12: =COUNTIFS(Assessment!$A$6:$A$115,A12,Assessment!$I$6:$I$115,"NOT ASSESSED") | F12: =SUMIF(Assessment!$A$6:$A$115,A12,Assessment!$L$6:$L$115) | G12: =SUMIF(Assessment!$A$6:$A$115,A12,Assessment!$N$6:$N$115) | H12: =IF(B12=0,0,(B12-E12)/B12) | I12: =F12-G12 | J12: =IF(E12>0,"INCOMPLETE",IF(D12=0,"READY","NEEDS WORK"))
A13: MP | B13: =COUNTIF(Assessment!$A$6:$A$115,A13) | C13: =COUNTIFS(Assessment!$A$6:$A$115,A13,Assessment!$I$6:$I$115,"MET") | D13: =COUNTIFS(Assessment!$A$6:$A$115,A13,Assessment!$I$6:$I$115,"NOT MET") | E13: =COUNTIFS(Assessment!$A$6:$A$115,A13,Assessment!$I$6:$I$115,"NOT ASSESSED") | F13: =SUMIF(Assessment!$A$6:$A$115,A13,Assessment!$L$6:$L$115) | G13: =SUMIF(Assessment!$A$6:$A$115,A13,Assessment!$N$6:$N$115) | H13: =IF(B13=0,0,(B13-E13)/B13) | I13: =F13-G13 | J13: =IF(E13>0,"INCOMPLETE",IF(D13=0,"READY","NEEDS WORK"))
A14: PS | B14: =COUNTIF(Assessment!$A$6:$A$115,A14) | C14: =COUNTIFS(Assessment!$A$6:$A$115,A14,Assessment!$I$6:$I$115,"MET") | D14: =COUNTIFS(Assessment!$A$6:$A$115,A14,Assessment!$I$6:$I$115,"NOT MET") | E14: =COUNTIFS(Assessment!$A$6:$A$115,A14,Assessment!$I$6:$I$115,"NOT ASSESSED") | F14: =SUMIF(Assessment!$A$6:$A$115,A14,Assessment!$L$6:$L$115) | G14: =SUMIF(Assessment!$A$6:$A$115,A14,Assessment!$N$6:$N$115) | H14: =IF(B14=0,0,(B14-E14)/B14) | I14: =F14-G14 | J14: =IF(E14>0,"INCOMPLETE",IF(D14=0,"READY","NEEDS WORK"))
A15: PE | B15: =COUNTIF(Assessment!$A$6:$A$115,A15) | C15: =COUNTIFS(Assessment!$A$6:$A$115,A15,Assessment!$I$6:$I$115,"MET") | D15: =COUNTIFS(Assessment!$A$6:$A$115,A15,Assessment!$I$6:$I$115,"NOT MET") | E15: =COUNTIFS(Assessment!$A$6:$A$115,A15,Assessment!$I$6:$I$115,"NOT ASSESSED") | F15: =SUMIF(Assessment!$A$6:$A$115,A15,Assessment!$L$6:$L$115) | G15: =SUMIF(Assessment!$A$6:$A$115,A15,Assessment!$N$6:$N$115) | H15: =IF(B15=0,0,(B15-E15)/B15) | I15: =F15-G15 | J15: =IF(E15>0,"INCOMPLETE",IF(D15=0,"READY","NEEDS WORK"))
A16: RA | B16: =COUNTIF(Assessment!$A$6:$A$115,A16) | C16: =COUNTIFS(Assessment!$A$6:$A$115,A16,Assessment!$I$6:$I$115,"MET") | D16: =COUNTIFS(Assessment!$A$6:$A$115,A16,Assessment!$I$6:$I$115,"NOT MET") | E16: =COUNTIFS(Assessment!$A$6:$A$115,A16,Assessment!$I$6:$I$115,"NOT ASSESSED") | F16: =SUMIF(Assessment!$A$6:$A$115,A16,Assessment!$L$6:$L$115) | G16: =SUMIF(Assessment!$A$6:$A$115,A16,Assessment!$N$6:$N$115) | H16: =IF(B16=0,0,(B16-E16)/B16) | I16: =F16-G16 | J16: =IF(E16>0,"INCOMPLETE",IF(D16=0,"READY","NEEDS WORK"))
A17: CA | B17: =COUNTIF(Assessment!$A$6:$A$115,A17) | C17: =COUNTIFS(Assessment!$A$6:$A$115,A17,Assessment!$I$6:$I$115,"MET") | D17: =COUNTIFS(Assessment!$A$6:$A$115,A17,Assessment!$I$6:$I$115,"NOT MET") | E17: =COUNTIFS(Assessment!$A$6:$A$115,A17,Assessment!$I$6:$I$115,"NOT ASSESSED") | F17: =SUMIF(Assessment!$A$6:$A$115,A17,Assessment!$L$6:$L$115) | G17: =SUMIF(Assessment!$A$6:$A$115,A17,Assessment!$N$6:$N$115) | H17: =IF(B17=0,0,(B17-E17)/B17) | I17: =F17-G17 | J17: =IF(E17>0,"INCOMPLETE",IF(D17=0,"READY","NEEDS WORK"))
... A19: SI | B19: =COUNTIF(Assessment!$A$6:$A$115,A19) | C19: =COUNTIFS(Assessment!$A$6:$A$115,A19,Assessment!$I$6:$I$115,"MET") | D19: =COUNTIFS(Assessment!$A$6:$A$115,A19,Assessment!$I$6:$I$115,"NOT MET") | E19: =COUNTIFS(Assessment!$A$6:$A$115,A19,Assessment!$I$6:$I$115,"NOT ASSESSED") | F19: =SUMIF(Assessment!$A$6:$A$115,A19,Assessment!$L$6:$L$115) | G19: =SUMIF(Assessment!$A$6:$A$115,A19,Assessment!$N$6:$N$115) | H19: =IF(B19=0,0,(B19-E19)/B19) | I19: =F19-G19 | J19: =IF(E19>0,"INCOMPLETE",IF(D19=0,"READY","NEEDS WORK"))

Sheet Evidence
A1: Evidence Register
A3: Track policies, procedures, configurations, interviews, tests, screenshots, and other supporting evidence.
B6: This module will be implemented in the next workbook sprint.

Sheet POA&M
A1: Plan of Action & Milestones
A3: Track remediation activities for findings assessed as NOT MET.
B6: This module will be implemented in the next workbook sprint.

Sheet SSP Crosswalk
A1: SSP Crosswalk
A3: Map CMMC requirements to System Security Plan sections, policies, procedures, and owners.
B6: This module will be implemented in the next workbook sprint.

Sheet Assessment History
A1: Assessment History
A3: Store historical assessment snapshots and track score and readiness trends.
B6: This module will be implemented in the next workbook sprint.

Sheet Executive Report
A1: Executive Report
A3: Printable management summary of assessment results, risks, and remediation priorities.
B6: This module will be implemented in the next workbook sprint.

Sheet Settings
A1: Workbook Settings
A3: Workbook configuration and official scoring metadata
B6: Workbook Version | C6: 0.2
B7: Assessment Guide Version | C7: 2.13
B8: Maximum Score | C8: 110
B9: Maximum Deduction | C9: 314
B10: Mathematical Minimum Score | C10: -204
B11: Requirement Count | C11: 110
B12: Partial Credit Requirements | C12: 2
B13: Assessment Level | C13: CMMC Level 2
B14: Scoring Source | C14: 32 CFR 170.24
B15: Workbook Generated By | C15: CMMC Assessment Platform

Sheet _Lists
A1: Assessment Status | B1: Evidence Status | C1: Yes / No | D1: Implementation State
A2: MET | B2: Not Started | C2: Yes | D2: FULLY IMPLEMENTED
A3: NOT MET | B3: In Progress | C3: No | D3: PARTIALLY IMPLEMENTED
A4: NOT APPLICABLE | B4: Complete | D4: NOT IMPLEMENTED
A5: NOT ASSESSED | B5: Not Applicable | D5: NOT APPLICABLE
D6: NOT ASSESSED
